Workbook
Name Slicer_Continent: #N/A

Sheet worldometer_data
A1: Country/Region | B1: Continent | C1: Population | D1: TotalCases | E1: NewCases | F1: TotalDeaths | G1: NewDeaths | H1: TotalRecovered | I1: NewRecovered | J1: ActiveCases | K1: Serious,Critical | L1: Tot Cases/1M pop | M1: Deaths/1M pop | N1: TotalTests | O1: Tests/1M pop | P1: WHO Region
A2: Brazil | B2: South America | C2: 212710692 | D2: 2917562 | F2: 98644 | H2: 2047660 | J2: 771258 | K2: 8318 | L2: 13716 | M2: 464 | N2: 13206188 | O2: 62085 | P2: Americas
A3: Peru | B3: South America | C3: 33016319 | D3: 455409 | F3: 20424 | H3: 310337 | J3: 124648 | K3: 1426 | L3: 13793 | M3: 619 | N3: 2493429 | O3: 75521 | P3: Americas
A4: Chile | B4: South America | C4: 19132514 | D4: 366671 | F4: 9889 | H4: 340168 | J4: 16614 | K4: 1358 | L4: 19165 | M4: 517 | N4: 1760615 | O4: 92022 | P4: Americas
A5: Colombia | B5: South America | C5: 50936262 | D5: 357710 | F5: 11939 | H5: 192355 | J5: 153416 | K5: 1493 | L5: 7023 | M5: 234 | N5: 1801835 | O5: 35374 | P5: Americas
A6: Argentina | B6: South America | C6: 45236884 | D6: 228195 | F6: 4251 | H6: 99852 | J6: 124092 | K6: 1150 | L6: 5044 | M6: 94 | N6: 794544 | O6: 17564 | P6: Americas
A7: Ecuador | B7: South America | C7: 17668824 | D7: 90537 | F7: 5877 | H7: 71318 | J7: 13342 | K7: 378 | L7: 5124 | M7: 333 | N7: 258582 | O7: 14635 | P7: Americas
A8: Bolivia | B8: South America | C8: 11688459 | D8: 86423 | E8: 1282 | F8: 3465 | G8: 80 | H8: 27373 | I8: 936 | J8: 55585 | K8: 71 | L8: 7394 | M8: 296 | N8: 183583 | O8: 15706 | P8: Americas
A9: Venezuela | B9: South America | C9: 28427499 | D9: 22299 | F9: 195 | H9: 12146 | J9: 9958 | K9: 42 | L9: 784 | M9: 7 | N9: 1567431 | O9: 55138 | P9: Americas
A10: French Guiana | B10: South America | C10: 299385 | D10: 8127 | F10: 47 | H10: 7240 | J10: 840 | K10: 23 | L10: 27146 | M10: 157 | N10: 41412 | O10: 138324
A11: Paraguay | B11: South America | C11: 7141091 | D11: 6375 | F11: 66 | H11: 4974 | J11: 1335 | K11: 23 | L11: 893 | M11: 9 | N11: 135277 | O11: 18943 | P11: Americas
A12: Suriname | B12: South America | C12: 587154 | D12: 2096 | F12: 29 | H12: 1446 | J12: 621 | K12: 9 | L12: 3570 | M12: 49 | N12: 2785 | O12: 4743 | P12: Americas
A13: Uruguay | B13: South America | C13: 3474956 | D13: 1318 | F13: 37 | H13: 1079 | J13: 202 | K13: 2 | L13: 379 | M13: 11 | N13: 126956 | O13: 36535 | P13: Americas
A14: Guyana | B14: South America | C14: 786936 | D14: 538 | F14: 22 | H14: 189 | J14: 327 | K14: 2 | L14: 684 | M14: 28 | N14: 5165 | O14: 6563 | P14: Americas
A15: Falkland Islands | B15: South America | C15: 3489 | D15: 13 | H15: 13 | J15: 0 | L15: 3726 | N15: 1816 | O15: 520493
A16: USA | B16: North America | C16: 331198130 | D16: 5032179 | F16: 162804 | H16: 2576668 | J16: 2292707 | K16: 18296 | L16: 15194 | M16: 492 | N16: 63139605 | O16: 190640 | P16: Americas
A17: Mexico | B17: North America | C17: 129066160 | D17: 462690 | E17: 6590 | F17: 50517 | G17: 819 | H17: 308848 | I17: 4140 | J17: 103325 | K17: 3987 | L17: 3585 | M17: 391 | N17: 1056915 | O17: 8189 | P17: Americas
A18: Canada | B18: North America | C18: 37775022 | D18: 118561 | F18: 8966 | H18: 103106 | J18: 6489 | K18: 2263 | L18: 3139 | M18: 237 | N18: 4319172 | O18: 114339 | P18: Americas
A19: Dominican Republic | B19: North America | C19: 10858648 | D19: 76536 | F19: 1246 | H19: 40539 | J19: 34751 | K19: 317 | L19: 7048 | M19: 115 | N19: 281926 | O19: 25963 | P19: Americas
A20: Panama | B20: North America | C20: 4321282 | D20: 71418 | F20: 1574 | H20: 45658 | J20: 24186 | K20: 161 | L20: 16527 | M20: 364 | N20: 240995 | O20: 55769 | P20: Americas
A21: Guatemala | B21: North America | C21: 17946899 | D21: 54339 | F21: 2119 | H21: 42070 | J21: 10150 | K21: 5 | L21: 3028 | M21: 118 | N21: 172712 | O21: 9624 | P21: Americas
A22: Honduras | B22: North America | C22: 9919704 | D22: 45098 | F22: 1423 | H22: 6116 | J22: 37559 | K22: 52 | L22: 4546 | M22: 143 | N22: 109292 | O22: 11018 | P22: Americas
A23: Costa Rica | B23: North America | C23: 5098730 | D23: 21070 | F23: 200 | H23: 7038 | J23: 13832 | K23: 103 | L23: 4132 | M23: 39 | N23: 96110 | O23: 18850 | P23: Americas
A24: El Salvador | B24: North America | C24: 6489514 | D24: 19126 | F24: 513 | H24: 9236 | J24: 9377 | K24: 509 | L24: 2947 | M24: 79 | N24: 251271 | O24: 38720 | P24: Americas
A25: Haiti | B25: North America | C25: 11416103 | D25: 7544 | F25: 171 | H25: 4832 | J25: 2541 | L25: 661 | M25: 15 | N25: 18443 | O25: 1616 | P25: Americas
A26: Nicaragua | B26: North America | C26: 6632263 | D26: 3902 | F26: 123 | H26: 2913 | J26: 866 | L26: 588 | M26: 19 | P26: Americas
A27: Cuba | B27: North America | C27: 11325899 | D27: 2775 | F27: 88 | H27: 2409 | J27: 278 | K27: 4 | L27: 245 | M27: 8 | N27: 285471 | O27: 25205 | P27: Americas
A28: Jamaica | B28: North America | C28: 2962478 | D28: 958 | E28: 30 | F28: 12 | H28: 745 | J28: 201 | L28: 323 | M28: 4 | N28: 41840 | O28: 14123 | P28: Americas
A29: Bahamas | B29: North America | C29: 393616 | D29: 761 | F29: 14 | H29: 91 | J29: 656 | K29: 1 | L29: 1933 | M29: 36 | N29: 4814 | O29: 12230 | P29: Americas
A30: Guadeloupe | B30: North America | C30: 400131 | D30: 279 | F30: 14 | H30: 179 | J30: 86 | L30: 697 | M30: 35 | N30: 18476 | O30: 46175
A31: Martinique | B31: North America | C31: 375235 | D31: 276 | F31: 15 | H31: 98 | J31: 163 | K31: 1 | L31: 736 | M31: 40 | N31: 12227 | O31: 32585
A32: Aruba | B32: North America | C32: 106812 | D32: 263 | F32: 3 | H32: 114 | J32: 146 | L32: 2462 | M32: 28 | N32: 14047 | O32: 131511
A33: Trinidad and Tobago | B33: North America | C33: 1399950 | D33: 210 | F33: 8 | H33: 135 | J33: 67 | L33: 150 | M33: 6 | N33: 9559 | O33: 6828 | P33: Americas
A34: Cayman Islands | B34: North America | C34: 65798 | D34: 203 | F34: 1 | H34: 202 | J34: 0 | L34: 3085 | M34: 15 | N34: 31108 | O34: 472780
A35: Sint Maarten | B35: North America | C35: 42924 | D35: 160 | F35: 16 | H35: 64 | J35: 80 | K35: 3 | L35: 3728 | M35: 373 | N35: 1115 | O35: 25976
A36: Bermuda | B36: North America | C36: 62254 | D36: 157 | F36: 9 | H36: 144 | J36: 4 | L36: 2522 | M36: 145 | N36: 26352 | O36: 423298 | P36: Americas
A37: Barbados | B37: North America | C37: 287411 | D37: 133 | F37: 7 | H37: 100 | J37: 26 | L37: 463 | M37: 24 | N37: 12233 | O37: 42563 | P37: Americas
A38: Turks and Caicos | B38: North America | C38: 38768 | D38: 129 | F38: 2 | H38: 39 | J38: 88 | K38: 3 | L38: 3327 | M38: 52 | N38: 1252 | O38: 32295
A39: Antigua and Barbuda | B39: North America | C39: 98010 | D39: 92 | F39: 3 | H39: 76 | J39: 13 | K39: 1 | L39: 939 | M39: 31 | N39: 1500 | O39: 15305 | P39: Americas
A40: Belize | B40: North America | C40: 398312 | D40: 86 | F40: 2 | H40: 31 | J40: 53 | K40: 2 | L40: 216 | M40: 5 | N40: 3679 | O40: 9236 | P40: Americas
...

Sheet analysis
A3: Row Labels | B3: Sum of TotalCases | F3: country | G3: case | H3: pupulation | J3: Row Labels | K3: Count of Country/Region | M3: Row Labels | N3: Sum of ActiveCases | O3: Sum of TotalRecovered | P3: Sum of TotalDeaths | R3: Row Labels | S3: Sum of ActiveCases | T3: Sum of TotalCases | V3: Row Labels | W3: Sum of TotalTests | Y3: Row Labels | Z3: Sum of NewCases | AA3: Sum of NewRecovered | AC3: Row Labels | AD3: Sum of Serious,Critical
A4: Afghanistan | B4: 36896 | F4: =VLOOKUP(A4,$A:$C,1,0) -> Afghanistan | G4: =VLOOKUP(A4,$A:$C,2,0) -> 36896 | H4: =VLOOKUP(A4,worldometer_data!$A:$C,3,FALSE) -> 39009447 | J4: Africa | K4: 57 | M4: Africa | N4: 296133 | O4: 693620 | P4: 22114 | R4: Bangladesh | S4: 102521 | T4: 249651 | V4: USA | W4: 63139605 | Y4: Mexico | Z4: 6590 | AA4: 4140 | AC4: USA | AD4: 18296
A5: Albania | B5: 6016 | F5: =VLOOKUP(A5,$A:$B,1,0) -> Albania | G5: =VLOOKUP(A5,$A:$B,2,0) -> 6016 | H5: =VLOOKUP(A5,worldometer_data!$A:$C,3,FALSE) -> 2877470 | J5: Asia | K5: 48 | M5: Asia | N5: 1080997 | O5: 3508170 | P5: 100627 | R5: Mexico | S5: 103325 | T5: 462690 | V5: Russia | W5: 29716907 | Y5: Bolivia | Z5: 1282 | AA5: 936 | AC5: India | AD5: 8944
A6: Algeria | B6: 33626 | F6: =VLOOKUP(A6,$A:$B,1,0) -> Algeria | G6: =VLOOKUP(A6,$A:$B,2,0) -> 33626 | H6: =VLOOKUP(A6,worldometer_data!$A:$C,3,FALSE) -> 43926079 | J6: Australia/Oceania | K6: 6 | M6: Australia/Oceania | N6: 8834 | O6: 12620 | P6: 281 | R6: Argentina | S6: 124092 | T6: 228195 | V6: India | W6: 22149351 | Y6: Jamaica | Z6: 30 | AC6: Brazil | AD6: 8318
A7: Andorra | B7: 944 | F7: =VLOOKUP(A7,$A:$B,1,0) -> Andorra | G7: =VLOOKUP(A7,$A:$B,2,0) -> 944 | H7: =VLOOKUP(A7,worldometer_data!$A:$C,3,FALSE) -> 77278 | J7: Europe | K7: 48 | M7: Europe | N7: 475261 | O7: 1587302 | P7: 205232 | R7: Peru | S7: 124648 | T7: 455409 | V7: UK | W7: 17515234 | Y7: S. Korea | Z7: 20 | AA7: 42 | AC7: Iran | AD7: 4156
A8: Angola | B8: 1483 | F8: =VLOOKUP(A8,$A:$B,1,0) -> Angola | G8: =VLOOKUP(A8,$A:$B,2,0) -> 1483 | H8: =VLOOKUP(A8,worldometer_data!$A:$C,3,FALSE) -> 32956300 | J8: North America | K8: 35 | M8: North America | N8: 2537676 | O8: 3151678 | P8: 229855 | R8: South Africa | S8: 141264 | T8: 538184 | V8: Brazil | W8: 13206188 | Y8: Nepal | AC8: Mexico | AD8: 3987
A9: Antigua and Barbuda | B9: 92 | F9: =VLOOKUP(A9,$A:$B,1,0) -> Antigua and Barbuda | G9: =VLOOKUP(A9,$A:$B,2,0) -> 92 | H9: =VLOOKUP(A9,worldometer_data!$A:$C,3,FALSE) -> 98010 | J9: South America | K9: 14 | M9: South America | N9: 1272238 | O9: 3116150 | P9: 154885 | R9: Colombia | S9: 153416 | T9: 357710 | V9: Germany | W9: 8586648 | Y9: Yemen | AC9: Russia | AD9: 2300
A10: Argentina | B10: 228195 | F10: =VLOOKUP(A10,$A:$B,1,0) -> Argentina | G10: =VLOOKUP(A10,$A:$B,2,0) -> 228195 | H10: =VLOOKUP(A10,worldometer_data!$A:$C,3,FALSE) -> 45236884 | M10: Total | N10: =MAX(N4:N8) -> 2537676 | O10: =MAX(O4:O9) -> 3508170 | P10: =MAX(P4:P9) -> 229855 | R10: Russia | S10: 180931 | T10: 871894 | V10: Italy | W10: 7099713 | Y10: Sint Maarten | AC10: Canada | AD10: 2263
A11: Armenia | B11: 39819 | F11: =VLOOKUP(A11,$A:$B,1,0) -> Armenia | G11: =VLOOKUP(A11,$A:$B,2,0) -> 39819 | H11: =VLOOKUP(A11,worldometer_data!$A:$C,3,FALSE) -> 2963811 | R11: India | S11: 606387 | T11: 2025409 | V11: Spain | W11: 7064329 | Y11: Antigua and Barbuda | AC11: Saudi Arabia | AD11: 1915
A12: Aruba | B12: 263 | F12: =VLOOKUP(A12,$A:$B,1,0) -> Aruba | G12: =VLOOKUP(A12,$A:$B,2,0) -> 263 | H12: =VLOOKUP(A12,worldometer_data!$A:$C,3,FALSE) -> 106812 | R12: Brazil | S12: 771258 | T12: 2917562 | V12: UAE | W12: 5262658 | Y12: Mali | AC12: Colombia | AD12: 1493
A13: Australia | B13: 19890 | F13: =VLOOKUP(A13,$A:$B,1,0) -> Australia | G13: =VLOOKUP(A13,$A:$B,2,0) -> 19890 | H13: =VLOOKUP(A13,worldometer_data!$A:$C,3,FALSE) -> 25528864 | R13: USA | S13: 2292707 | T13: 5032179 | V13: Turkey | W13: 5081802 | Y13: Argentina | AC13: Peru | AD13: 1426
A14: Austria | B14: 21696 | F14: =VLOOKUP(A14,$A:$B,1,0) -> Austria | G14: =VLOOKUP(A14,$A:$B,2,0) -> 21696 | H14: =VLOOKUP(A14,worldometer_data!$A:$C,3,FALSE) -> 9011577 | Y14: Philippines
A15: Azerbaijan | B15: 33247 | F15: =VLOOKUP(A15,$A:$B,1,0) -> Azerbaijan | G15: =VLOOKUP(A15,$A:$B,2,0) -> 33247 | H15: =VLOOKUP(A15,worldometer_data!$A:$C,3,FALSE) -> 10148243 | Y15: Armenia
A16: Bahamas | B16: 761 | F16: =VLOOKUP(A16,$A:$B,1,0) -> Bahamas | G16: =VLOOKUP(A16,$A:$B,2,0) -> 761 | H16: =VLOOKUP(A16,worldometer_data!$A:$C,3,FALSE) -> 393616 | Y16: Tanzania
A17: Bahrain | B17: 42889 | F17: =VLOOKUP(A17,$A:$B,1,0) -> Bahrain | G17: =VLOOKUP(A17,$A:$B,2,0) -> 42889 | H17: =VLOOKUP(A17,worldometer_data!$A:$C,3,FALSE) -> 1706669 | Y17: Aruba
A18: Bangladesh | B18: 249651 | F18: =VLOOKUP(A18,$A:$B,1,0) -> Bangladesh | G18: =VLOOKUP(A18,$A:$B,2,0) -> 249651 | H18: =VLOOKUP(A18,worldometer_data!$A:$C,3,FALSE) -> 164851401 | Y18: Liechtenstein
A19: Barbados | B19: 133 | F19: =VLOOKUP(A19,$A:$B,1,0) -> Barbados | G19: =VLOOKUP(A19,$A:$B,2,0) -> 133 | H19: =VLOOKUP(A19,worldometer_data!$A:$C,3,FALSE) -> 287411 | Y19: Australia
A20: Belarus | B20: 68503 | F20: =VLOOKUP(A20,$A:$B,1,0) -> Belarus | G20: =VLOOKUP(A20,$A:$B,2,0) -> 68503 | H20: =VLOOKUP(A20,worldometer_data!$A:$C,3,FALSE) -> 9449001 | Y20: Monaco
A21: Belgium | B21: 71158 | F21: =VLOOKUP(A21,$A:$B,1,0) -> Belgium | G21: =VLOOKUP(A21,$A:$B,2,0) -> 71158 | H21: =VLOOKUP(A21,worldometer_data!$A:$C,3,FALSE) -> 11594739 | Y21: Austria
A22: Belize | B22: 86 | F22: =VLOOKUP(A22,$A:$B,1,0) -> Belize | G22: =VLOOKUP(A22,$A:$B,2,0) -> 86 | H22: =VLOOKUP(A22,worldometer_data!$A:$C,3,FALSE) -> 398312 | Y22: Norway
A23: Benin | B23: 1936 | F23: =VLOOKUP(A23,$A:$B,1,0) -> Benin | G23: =VLOOKUP(A23,$A:$B,2,0) -> 1936 | H23: =VLOOKUP(A23,worldometer_data!$A:$C,3,FALSE) -> 12151976 | Y23: Azerbaijan
A24: Bermuda | B24: 157 | F24: =VLOOKUP(A24,$A:$B,1,0) -> Bermuda | G24: =VLOOKUP(A24,$A:$B,2,0) -> 157 | H24: =VLOOKUP(A24,worldometer_data!$A:$C,3,FALSE) -> 62254 | Y24: San Marino
A25: Bhutan | B25: 105 | F25: =VLOOKUP(A25,$A:$B,1,0) -> Bhutan | G25: =VLOOKUP(A25,$A:$B,2,0) -> 105 | H25: =VLOOKUP(A25,worldometer_data!$A:$C,3,FALSE) -> 772443 | Y25: Bahamas
... A211: Zimbabwe | B211: 4339 | F211: =VLOOKUP(A211,$A:$B,1,0) -> Zimbabwe | G211: =VLOOKUP(A211,$A:$B,2,0) -> 4339 | H211: =VLOOKUP(A211,worldometer_data!$A:$C,3,FALSE) -> 14883803 | Y211: Kyrgyzstan
F212: =VLOOKUP(A212,$A:$B,1,0) -> #N/A | G212: =VLOOKUP(A212,$A:$B,2,0) -> #N/A | H212: =VLOOKUP(A212,worldometer_data!$A:$C,3,FALSE) -> #N/A

Sheet Dashboard

Sheet Project Info
F30: GitHub: deep-gaikwad | I30: LinkedIn: deepgaikwad
